#VRML_SIM R2023b utf8
# license: Apache License 2.0
# license url: http://www.apache.org/licenses/LICENSE-2.0
# This is a proto file for Webots for the Firefighter
# Extracted from: D:\Elephantrobotics\webots_project\mycobot_webots\../mercury_b1/../mercury_b1/mercury_b1.urdf

PROTO mercury_b1 [
  field  SFVec3f     translation     0 0 0
  field  SFRotation  rotation        0 0 1 0
  field  SFString    name            "mercury_b1"  # Is `Robot.name`.
  field  SFString    controller      "b1_controller"         # Is `Robot.controller`.
  field  MFString    controllerArgs  []             # Is `Robot.controllerArgs`.
  field  SFString    customData      ""             # Is `Robot.customData`.
  field  SFBool      supervisor      FALSE          # Is `Robot.supervisor`.
  field  SFBool      synchronization TRUE           # Is `Robot.synchronization`.
  field  SFBool      selfCollision   FALSE          # Is `Robot.selfCollision`.
]
{
  Robot {
    translation IS translation
    rotation IS rotation
    controller IS controller
    controllerArgs IS controllerArgs
    customData IS customData
    supervisor IS supervisor
    synchronization IS synchronization
    selfCollision IS selfCollision
    children [
      DEF base_visual CadShape {
        url "../mercury_b1/base.dae"
      }
      HingeJoint {
        jointParameters HingeJointParameters {
          axis 0.000000 0.000000 1.000000
          anchor 0.000000 0.000000 0.231000
        }
        device [
          RotationalMotor {
            name "body"
            minPosition -2.0594
            maxPosition 2.0594
            maxTorque 1000.0
          }
          PositionSensor {
            name "body_sensor"
          }
        ]
        endPoint Solid {
          translation 0.000000 0.000000 0.231000
          children [
            Pose {
              translation 0.000000 0.000000 -0.110000
              children [
                DEF body_visual CadShape {
                  url "../mercury_b1/body.dae"
                }
              ]
            }
            HingeJoint {
              jointParameters HingeJointParameters {
                axis 0.499914 0.866075 -0.000004
                anchor 0.075000 0.186000 0.085000
              }
              device [
                RotationalMotor {
                  name "joint1_L"
                  minPosition -3.1066
                  maxPosition 3.1066
                  maxTorque 1000.0
                }
                PositionSensor {
                  name "joint1_L_sensor"
                }
              ]
              endPoint Solid {
                translation 0.075000 0.186000 0.085000
                rotation -0.935137 0.250520 -0.250519 1.637813
                children [
                  Pose {
                    translation 0.000000 0.000000 -0.084000
                    children [
                      DEF joint1_L_visual CadShape {
                        url "../mercury_b1/joint1_L.dae"
                      }
                    ]
                  }
                  HingeJoint {
                    jointParameters HingeJointParameters {
                      axis 0.000000 1.000000 -0.000004
                    }
                    device [
                      RotationalMotor {
                        name "joint2_L"
                        minPosition -1.4311
                        maxPosition 2.2689
                        maxTorque 1000.0
                      }
                      PositionSensor {
                        name "joint2_L_sensor"
                      }
                    ]
                    endPoint Solid {
                      rotation -1.000000 0.000000 0.000000 1.570800
                      children [
                        Pose {
                          rotation 0.707105 -0.707108 -0.000001 3.141591
                          children [
                            DEF joint2_L_visual CadShape {
                              url "../mercury_b1/joint2_L.dae"
                            }
                          ]
                        }
                        HingeJoint {
                          jointParameters HingeJointParameters {
                            axis 0.000000 -1.000000 -0.000004
                            anchor 0.000000 -0.110000 0.000000
                          }
                          device [
                            RotationalMotor {
                              name "joint3_L"
                              minPosition -3.1066
                              maxPosition 3.1066
                              maxTorque 1000.0
                            }
                            PositionSensor {
                              name "joint3_L_sensor"
                            }
                          ]
                          endPoint Solid {
                            translation 0.000000 -0.110000 0.000000
                            rotation 1.000000 0.000000 0.000000 1.570800
                            children [
                              Pose {
                                translation 0.000000 0.000000 0.038000
                                children [
                                  DEF joint3_L_visual CadShape {
                                    url "../mercury_b1/joint3_L.dae"
                                  }
                                ]
                              }
                              HingeJoint {
                                jointParameters HingeJointParameters {
                                  axis -0.000003 -1.000000 -0.000004
                                  anchor 0.030000 0.000000 0.095000
                                }
                                device [
                                  RotationalMotor {
                                    name "joint4_L"
                                    minPosition -3.0543
                                    maxPosition 0.2617
                                    maxTorque 1000.0
                                  }
                                  PositionSensor {
                                    name "joint4_L_sensor"
                                  }
                                ]
                                endPoint Solid {
                                  translation 0.030000 0.000000 0.095000
                                  rotation -0.000001 -0.707108 0.707105 3.141591
                                  children [
                                    Pose {
                                      rotation 0.000000 0.000000 -1.000000 1.570800
                                      children [
                                        DEF joint4_L_visual CadShape {
                                          url "../mercury_b1/joint4_L.dae"
                                        }
                                      ]
                                    }
                                    HingeJoint {
                                      jointParameters HingeJointParameters {
                                        axis -0.000000 -1.000000 0.000004
                                        anchor 0.030000 -0.126000 0.000000
                                      }
                                      device [
                                        RotationalMotor {
                                          name "joint5_L"
                                          minPosition -3.1066
                                          maxPosition 3.1066
                                          maxTorque 1000.0
                                        }
                                        PositionSensor {
                                          name "joint5_L_sensor"
                                        }
                                      ]
                                      endPoint Solid {
                                        translation 0.030000 -0.126000 0.000000
                                        rotation 0.000001 0.707105 -0.707108 3.141591
                                        children [
                                          Pose {
                                            translation 0.000000 0.000000 -0.069000
                                            children [
                                              DEF joint5_L_visual CadShape {
                                                url "../mercury_b1/joint5_L.dae"
                                              }
                                            ]
                                          }
                                          HingeJoint {
                                            jointParameters HingeJointParameters {
                                              axis 0.000000 -1.000000 -0.000004
                                              anchor 0.000000 0.000000 0.080000
                                            }
                                            device [
                                              RotationalMotor {
                                                name "joint6_L"
                                                minPosition -0.0174
                                                maxPosition 2.9321
                                                maxTorque 1000.0
                                              }
                                              PositionSensor {
                                                name "joint6_L_sensor"
                                              }
                                            ]
                                            endPoint Solid {
                                              translation 0.000000 0.000000 0.080000
                                              rotation 1.000000 0.000000 0.000000 1.570800
                                              children [
                                                Pose {
                                                  translation 0.000000 0.000000 -0.025000
                                                  rotation 0.000000 0.000000 -1.000000 1.570800
                                                  children [
                                                    DEF joint6_L_visual CadShape {
                                                      url "../mercury_b1/joint6_L.dae"
                                                    }
                                                  ]
                                                }
                                                HingeJoint {
                                                  jointParameters HingeJointParameters {
                                                    axis 0.000000 -1.000000 -0.000004
                                                    anchor 0.038000 -0.046000 0.000000
                                                  }
                                                  device [
                                                    RotationalMotor {
                                                      name "joint7_L"
                                                      minPosition -3.1066
                                                      maxPosition 3.1066
                                                      maxTorque 1000.0
                                                    }
                                                    PositionSensor {
                                                      name "joint7_L_sensor"
                                                    }
                                                  ]
                                                  endPoint Solid {
                                                    translation 0.038000 -0.046000 0.000000
                                                    rotation 1.000000 0.000000 0.000000 1.570800
                                                    children [
                                                      Pose {
                                                        translation 0.000000 0.000000 -0.002000
                                                        rotation 0.000000 0.000000 -1.000000 1.570800
                                                        children [
                                                          DEF joint7_L_visual CadShape {
                                                            url "../mercury_b1/joint7_L.dae"
                                                          }
                                                        ]
                                                      }
                                                    ]
                                                    name "link7_L"
                                                    boundingObject Pose {
                                                      translation 0.000000 0.000000 -0.002000
                                                      rotation 0.000000 0.000000 -1.000000 1.570800
                                                      children [
                                                        DEF joint7_L Mesh {
                                                          url "../mercury_b1/joint7_L.dae"
                                                        }
                                                      ]
                                                    }
                                                    physics Physics {
                                                    }
                                                  }
                                                }
                                              ]
                                              name "link6_L"
                                              boundingObject Pose {
                                                translation 0.000000 0.000000 -0.025000
                                                rotation 0.000000 0.000000 -1.000000 1.570800
                                                children [
                                                  DEF joint6_L Mesh {
                                                    url "../mercury_b1/joint6_L.dae"
                                                  }
                                                ]
                                              }
                                              physics Physics {
                                              }
                                            }
                                          }
                                        ]
                                        name "link5_L"
                                        boundingObject Pose {
                                          translation 0.000000 0.000000 -0.069000
                                          children [
                                            DEF joint5_L Mesh {
                                              url "../mercury_b1/joint5_L.dae"
                                            }
                                          ]
                                        }
                                        physics Physics {
                                        }
                                      }
                                    }
                                  ]
                                  name "link4_L"
                                  boundingObject Pose {
                                    rotation 0.000000 0.000000 -1.000000 1.570800
                                    children [
                                      DEF joint4_L Mesh {
                                        url "../mercury_b1/joint4_L.dae"
                                      }
                                    ]
                                  }
                                  physics Physics {
                                  }
                                }
                              }
                            ]
                            name "link3_L"
                            boundingObject Pose {
                              translation 0.000000 0.000000 0.038000
                              children [
                                DEF joint3_L Mesh {
                                  url "../mercury_b1/joint3_L.dae"
                                }
                              ]
                            }
                            physics Physics {
                            }
                          }
                        }
                      ]
                      name "link2_L"
                      boundingObject Pose {
                        rotation 0.707105 -0.707108 -0.000001 3.141591
                        children [
                          DEF joint2_L Mesh {
                            url "../mercury_b1/joint2_L.dae"
                          }
                        ]
                      }
                      physics Physics {
                      }
                    }
                  }
                ]
                name "link1_L"
                boundingObject Pose {
                  translation 0.000000 0.000000 -0.084000
                  children [
                    DEF joint1_L Mesh {
                      url "../mercury_b1/joint1_L.dae"
                    }
                  ]
                }
                physics Physics {
                }
              }
            }
            HingeJoint {
              jointParameters HingeJointParameters {
                axis 0.499914 -0.866075 -0.000004
                anchor 0.075000 -0.186000 0.085000
              }
              device [
                RotationalMotor {
                  name "joint1_R"
                  minPosition -3.1066
                  maxPosition 3.1066
                  maxTorque 1000.0
                }
                PositionSensor {
                  name "joint1_R_sensor"
                }
              ]
              endPoint Solid {
                translation 0.075000 -0.186000 0.085000
                rotation 0.935137 0.250520 0.250519 1.637813
                children [
                  Pose {
                    translation 0.000000 0.000000 -0.084000
                    children [
                      DEF joint1_R_visual CadShape {
                        url "../mercury_b1/joint1_R.dae"
                      }
                    ]
                  }
                  HingeJoint {
                    jointParameters HingeJointParameters {
                      axis 0.000000 1.000000 -0.000004
                    }
                    device [
                      RotationalMotor {
                        name "joint2_R"
                        minPosition -1.4311
                        maxPosition 2.2689
                        maxTorque 1000.0
                      }
                      PositionSensor {
                        name "joint2_R_sensor"
                      }
                    ]
                    endPoint Solid {
                      rotation -1.000000 0.000000 0.000000 1.570800
                      children [
                        Pose {
                          rotation 0.707105 -0.707108 -0.000001 3.141591
                          children [
                            DEF joint2_R_visual CadShape {
                              url "../mercury_b1/joint2_R.dae"
                            }
                          ]
                        }
                        HingeJoint {
                          jointParameters HingeJointParameters {
                            axis 0.000000 -1.000000 -0.000004
                            anchor 0.000000 -0.110000 0.000000
                          }
                          device [
                            RotationalMotor {
                              name "joint3_R"
                              minPosition -3.1066
                              maxPosition 3.1066
                              maxTorque 1000.0
                            }
                            PositionSensor {
                              name "joint3_R_sensor"
                            }
                          ]
                          endPoint Solid {
                            translation 0.000000 -0.110000 0.000000
                            rotation 1.000000 0.000000 0.000000 1.570800
                            children [
                              Pose {
                                translation 0.000000 0.000000 0.038000
                                children [
                                  DEF joint3_R_visual CadShape {
                                    url "../mercury_b1/joint3_R.dae"
                                  }
                                ]
                              }
                              HingeJoint {
                                jointParameters HingeJointParameters {
                                  axis -0.000003 -1.000000 -0.000004
                                  anchor 0.030000 0.000000 0.095000
                                }
                                device [
                                  RotationalMotor {
                                    name "joint4_R"
                                    minPosition -3.0543
                                    maxPosition 0.2617
                                    maxTorque 1000.0
                                  }
                                  PositionSensor {
                                    name "joint4_R_sensor"
                                  }
                                ]
                                endPoint Solid {
                                  translation 0.030000 0.000000 0.095000
                                  rotation -0.000001 -0.707108 0.707105 3.141591
                                  children [
                                    Pose {
                                      rotation 0.000000 0.000000 -1.000000 1.570800
                                      children [
                                        DEF joint4_R_visual CadShape {
                                          url "../mercury_b1/joint4_R.dae"
                                        }
                                      ]
                                    }
                                    HingeJoint {
                                      jointParameters HingeJointParameters {
                                        axis -0.000000 -1.000000 0.000004
                                        anchor 0.030000 -0.126000 0.000000
                                      }
                                      device [
                                        RotationalMotor {
                                          name "joint5_R"
                                          minPosition -3.1066
                                          maxPosition 3.1066
                                          maxTorque 1000.0
                                        }
                                        PositionSensor {
                                          name "joint5_R_sensor"
                                        }
                                      ]
                                      endPoint Solid {
                                        translation 0.030000 -0.126000 0.000000
                                        rotation 0.000001 0.707105 -0.707108 3.141591
                                        children [
                                          Pose {
                                            translation 0.000000 0.000000 -0.069000
                                            children [
                                              DEF joint5_R_visual CadShape {
                                                url "../mercury_b1/joint5_R.dae"
                                              }
                                            ]
                                          }
                                          HingeJoint {
                                            jointParameters HingeJointParameters {
                                              axis 0.000000 -1.000000 -0.000004
                                              anchor 0.000000 0.000000 0.080000
                                            }
                                            device [
                                              RotationalMotor {
                                                name "joint6_R"
                                                minPosition -0.0174
                                                maxPosition 2.9321
                                                maxTorque 1000.0
                                              }
                                              PositionSensor {
                                                name "joint6_R_sensor"
                                              }
                                            ]
                                            endPoint Solid {
                                              translation 0.000000 0.000000 0.080000
                                              rotation 1.000000 0.000000 0.000000 1.570800
                                              children [
                                                Pose {
                                                  translation 0.000000 0.000000 -0.025000
                                                  rotation 0.000000 0.000000 -1.000000 1.570800
                                                  children [
                                                    DEF joint6_R_visual CadShape {
                                                      url "../mercury_b1/joint6_R.dae"
                                                    }
                                                  ]
                                                }
                                                HingeJoint {
                                                  jointParameters HingeJointParameters {
                                                    axis 0.000000 -1.000000 -0.000004
                                                    anchor 0.038000 -0.046000 0.000000
                                                  }
                                                  device [
                                                    RotationalMotor {
                                                      name "joint7_R"
                                                      minPosition -3.1066
                                                      maxPosition 3.1066
                                                      maxTorque 1000.0
                                                    }
                                                    PositionSensor {
                                                      name "joint7_R_sensor"
                                                    }
                                                  ]
                                                  endPoint Solid {
                                                    translation 0.038000 -0.046000 0.000000
                                                    rotation 1.000000 0.000000 0.000000 1.570800
                                                    children [
                                                      Pose {
                                                        translation 0.000000 0.000000 -0.002000
                                                        rotation 0.000000 0.000000 -1.000000 1.570800
                                                        children [
                                                          DEF joint7_R_visual CadShape {
                                                            url "../mercury_b1/joint7_R.dae"
                                                          }
                                                        ]
                                                      }
                                                    ]
                                                    name "link7_R"
                                                    boundingObject Pose {
                                                      translation 0.000000 0.000000 -0.002000
                                                      rotation 0.000000 0.000000 -1.000000 1.570800
                                                      children [
                                                        DEF joint7_R Mesh {
                                                          url "../mercury_b1/joint7_R.dae"
                                                        }
                                                      ]
                                                    }
                                                    physics Physics {
                                                    }
                                                  }
                                                }
                                              ]
                                              name "link6_R"
                                              boundingObject Pose {
                                                translation 0.000000 0.000000 -0.025000
                                                rotation 0.000000 0.000000 -1.000000 1.570800
                                                children [
                                                  DEF joint6_R Mesh {
                                                    url "../mercury_b1/joint6_R.dae"
                                                  }
                                                ]
                                              }
                                              physics Physics {
                                              }
                                            }
                                          }
                                        ]
                                        name "link5_R"
                                        boundingObject Pose {
                                          translation 0.000000 0.000000 -0.069000
                                          children [
                                            DEF joint5_R Mesh {
                                              url "../mercury_b1/joint5_R.dae"
                                            }
                                          ]
                                        }
                                        physics Physics {
                                        }
                                      }
                                    }
                                  ]
                                  name "link4_R"
                                  boundingObject Pose {
                                    rotation 0.000000 0.000000 -1.000000 1.570800
                                    children [
                                      DEF joint4_R Mesh {
                                        url "../mercury_b1/joint4_R.dae"
                                      }
                                    ]
                                  }
                                  physics Physics {
                                  }
                                }
                              }
                            ]
                            name "link3_R"
                            boundingObject Pose {
                              translation 0.000000 0.000000 0.038000
                              children [
                                DEF joint3_R Mesh {
                                  url "../mercury_b1/joint3_R.dae"
                                }
                              ]
                            }
                            physics Physics {
                            }
                          }
                        }
                      ]
                      name "link2_R"
                      boundingObject Pose {
                        rotation 0.707105 -0.707108 -0.000001 3.141591
                        children [
                          DEF joint2_R Mesh {
                            url "../mercury_b1/joint2_R.dae"
                          }
                        ]
                      }
                      physics Physics {
                      }
                    }
                  }
                ]
                name "link1_R"
                boundingObject Pose {
                  translation 0.000000 0.000000 -0.084000
                  children [
                    DEF joint1_R Mesh {
                      url "../mercury_b1/joint1_R.dae"
                    }
                  ]
                }
                physics Physics {
                }
              }
            }
            HingeJoint {
              jointParameters HingeJointParameters {
                axis 0.000000 0.000000 1.000000
                anchor 0.000000 0.000000 0.220000
              }
              device [
                RotationalMotor {
                  name "head"
                  minPosition -2.4085
                  maxPosition 3.2812
                  maxTorque 1000.0
                }
                PositionSensor {
                  name "head_sensor"
                }
              ]
              endPoint Solid {
                translation 0.000000 0.000000 0.220000
                children [
                  Pose {
                    translation 0.000000 0.000000 -0.100000
                    children [
                      DEF head_visual CadShape {
                        url "../mercury_b1/head.dae"
                      }
                    ]
                  }
                  HingeJoint {
                    jointParameters HingeJointParameters {
                      axis 0.000000 -1.000000 -0.000004
                      anchor 0.030000 0.000000 -0.080000
                    }
                    device [
                      RotationalMotor {
                        name "eye"
                        maxPosition 0.8377
                        maxTorque 1000.0
                      }
                      PositionSensor {
                        name "eye_sensor"
                      }
                    ]
                    endPoint Solid {
                      translation 0.030000 0.000000 -0.080000
                      rotation 1.000000 0.000000 0.000000 1.570800
                      children [
                        DEF head_eye_visual CadShape {
                          url "../mercury_b1/head_eye.dae"
                        }
                      ]
                      name "link_eye"
                      boundingObject Pose {
                        translation 0.000000 0.000000 -0.100000
                        children [
                          DEF head_eye Mesh {
                            url "../mercury_b1/head_eye.dae"
                          }
                        ]
                      }
                      physics Physics {
                      }
                    }
                  }
                ]
                name "link_head"
                boundingObject Pose {
                  translation 0.000000 0.000000 -0.100000
                  children [
                    DEF head Mesh {
                      url "../mercury_b1/head.dae"
                    }
                  ]
                }
                physics Physics {
                }
              }
            }
          ]
          name "link_body"
          boundingObject Pose {
            translation 0.000000 0.000000 -0.110000
            children [
              DEF body Mesh {
                url "../mercury_b1/body.dae"
              }
            ]
          }
          physics Physics {
          }
        }
      }
    ]
    name IS name
    boundingObject DEF base Mesh {
      url "../mercury_b1/base.dae"
    }
    physics Physics {
    }
  }
}
