<?xml version="1.0"?>
<robot  xmlns:xacro="http://www.ros.org/wiki/xacro" name="firefighter" >
	
<xacro:property name="width" value=".2" />

  <mujoco>
        <compiler 
        meshdir="../meshes_mujoco/" 
        balanceinertia="true" 
        discardvisual="false" />
  </mujoco>
  
  <link name="base">
    <visual>
      <geometry>
       <mesh filename="./base.stl"/>
      </geometry>
      <origin xyz = "0.0 0 0 " rpy = " 0 0 0"/>
    </visual>
    <collision>
      <geometry>
       <mesh filename="./base.stl"/>
        </geometry>
        <origin xyz = "0.0 0 0 " rpy = " 0 0 0"/>
    </collision>
  </link>

  <link name="joint1">
    <visual>
      <geometry>
       <mesh filename="./joint1.stl"/>
      </geometry>
      <origin xyz = "0.0 0 -0.08 " rpy = " 0 0 0"/>
    </visual>
    <collision>
     <geometry>
       <mesh filename="./joint1.stl"/>
      </geometry>
      <origin xyz = "0.0 0 -0.08 " rpy = " 0 0 0"/>
    </collision>
  </link>

  <link name="joint2">
    <visual>
      <geometry>
       <mesh filename="./joint2.stl"/>
      </geometry>
    <origin xyz = "0.0 0 0.0 " rpy = " 3.14159 0 -1.5708 "/>
    </visual>
    <collision>
      <geometry>
       <mesh filename="./joint2.stl"/>
      </geometry>
      <origin xyz = "0.0 0 0.0 " rpy = " 3.14159 0 -1.5708"/>
    </collision>
  </link>

  <link name="joint3">
    <visual>
      <geometry>
       
       <mesh filename="./joint3.stl"/>
      </geometry>
      <origin xyz = "0.0 0 0.038 " rpy = " 0 0 0"/>
    </visual>
    <collision>
      <geometry>
       <mesh filename="./joint3.stl"/>
      </geometry>
      <origin xyz = "0.0 0 0.038" rpy = " 0 0 0"/>
    </collision>
  </link>


  <link name="joint4">
    <visual>
      <geometry>
       <mesh filename="./joint4.stl"/>
      </geometry>
    <origin xyz = "0.0 0 0 " rpy = " 0 0 -1.5708"/>
    </visual>
    <collision>
       <geometry>
       <mesh filename="./joint4.stl"/>
      </geometry>
      <origin xyz = "0.0 0 0 " rpy = " 0 0 -1.5708"/>
    </collision>
  </link>


  <link name="joint5">
    <visual>
      <geometry>
       
       <mesh filename="./joint5.stl"/>
      </geometry>
    <origin xyz = "0 0 -0.069 " rpy = " 0 0 0"/>
    </visual>
    <collision>
      <geometry>
       
       <mesh filename="./joint5.stl"/>
      </geometry>
    <origin xyz = "0 0 -0.069 " rpy = " 0 0 0"/>
    </collision>
  </link>


  <link name="joint6">
    <visual>
      <geometry>
       
       <mesh filename="./joint6.stl"/>
      </geometry>
    <origin xyz = "0.0 0 -0.025 " rpy = " 0 0 -1.5708"/>
    </visual>
    <collision>
      <geometry>
       
       <mesh filename="./joint6.stl"/>
      </geometry>
    <origin xyz = "0.0 0 -0.025 " rpy = " 0 0 -1.5708"/>
    </collision>
  </link>

  <link name="joint7">
    <visual>
      <geometry>
       
       <mesh filename="./joint7.stl"/>
      </geometry>
    <origin xyz = "0.0 0 -0.002 " rpy = " 0 0 -1.5708"/>
    </visual>
    <collision>
      <geometry>
       
       <mesh filename="./joint7.stl"/>
      </geometry>
    <origin xyz = "0.0 0 -0.002 " rpy = " 0 0 -1.5708"/>
    </collision>
  </link>


  <joint name="joint1_to_base" type="revolute">
    <axis xyz="0 0 1"/>
    <limit effort = "1000.0" lower = "-3.10" upper = "3.10" velocity = "0"/>
    <parent link="base"/>
    <child link="joint1"/>
    <origin xyz= "0 0 99" rpy = "0 0 0"/>  
  </joint>


  <joint name="joint2_to_joint1" type="revolute">
    <axis xyz="0 0 1"/>
    <limit effort = "1000.0" lower = "-1.42" upper = "2.26" velocity = "0"/>
    <parent link="joint1"/>
    <child link="joint2"/>
    <origin xyz= "0 0  80" rpy = "-1.5708 0 0"/>  
  </joint>


  <joint name="joint3_to_joint2" type="revolute">
    <axis xyz=" 0 0 1"/>
    <limit effort = "1000.0" lower = "-3.10" upper = "3.10" velocity = "0"/>
    <parent link="joint2"/>
    <child link="joint3"/>
    <origin xyz= "0 -125 0   " rpy = "1.5708 0 0"/>  
  </joint>


 
  <joint name="joint4_to_joint3" type="revolute">
    <axis xyz=" 0 0 1"/>
    <limit effort = "1000.0" lower = "-3.0543" upper = "0.2617" velocity = "0"/>
    <parent link="joint3"/>
    <child link="joint4"/>
    <origin xyz= "30 0 58" rpy = "-1.5708 0 3.14159"/>  
  </joint>


  <joint name="joint5_to_joint4" type="revolute">
    <axis xyz="0 0 1"/>
    <limit effort = "1000.0" lower = "-3.10" upper = "3.10" velocity = "0"/>
    <parent link="joint4"/>
    <child link="joint5"/>
    <origin xyz= "30 -56 0" rpy = "1.5708 3.14159 0"/>  
  </joint>


  <joint name="joint6_to_joint5" type="revolute">
    <axis xyz="0 0 1"/>
    <limit effort = "1000.0" lower = "-0.0349" upper = "2.9321" velocity = "0"/>
    <parent link="joint5"/>
    <child link="joint6"/>
    <origin xyz= "0 25 150" rpy = "1.5708 0 0"/>  
  </joint>
 
  <joint name="joint7_to_joint6" type="revolute">
    <axis xyz="0 0 1"/>
    <limit effort = "1000.0" lower = "-3.10" upper = "3.10" velocity = "0"/>
    <parent link="joint6"/>
    <child link="joint7"/>
    <origin xyz= "38 -43 25" rpy = "1.5708 0 0"/>  
  </joint>



</robot>

