#VRML_SIM R2023b utf8
# license: Apache License 2.0
# license url: http://www.apache.org/licenses/LICENSE-2.0
# This is a proto file for Webots for the Firefighter
# Extracted from: D:\Elephantrobotics\webots_project\mycobot_webots\../mercury_a1/../mercury_a1/mercury_a1.urdf

PROTO mercury_a1 [
  field  SFVec3f     translation     0 0 0
  field  SFRotation  rotation        0 0 1 0
  field  SFString    name            "mercury_a1"  # Is `Robot.name`.
  field  SFString    controller      "a1_controller"         # Is `Robot.controller`.
  field  MFString    controllerArgs  []             # Is `Robot.controllerArgs`.
  field  SFString    customData      ""             # Is `Robot.customData`.
  field  SFBool      supervisor      FALSE          # Is `Robot.supervisor`.
  field  SFBool      synchronization TRUE           # Is `Robot.synchronization`.
  field  SFBool      selfCollision   FALSE          # Is `Robot.selfCollision`.
]
{
  Robot {
    translation IS translation
    rotation IS rotation
    controller IS controller
    controllerArgs IS controllerArgs
    customData IS customData
    supervisor IS supervisor
    synchronization IS synchronization
    selfCollision IS selfCollision
    children [
      DEF base_visual CadShape {
        url "../mercury_a1/base.dae"
      }
      HingeJoint {
        jointParameters HingeJointParameters {
          axis 0.000000 0.000000 1.000000
          anchor 0.000000 0.000000 0.175000
        }
        device [
          RotationalMotor {
            name "joint1_to_base"
            minPosition -2.8797
            maxPosition 2.8797
            maxTorque 1000.0
          }
          PositionSensor {
            name "joint1_to_base_sensor"
          }
        ]
        endPoint Solid {
          translation 0.000000 0.000000 0.175000
          children [
            Pose {
              translation 0.000000 0.000000 -0.080000
              children [
                DEF joint1_visual CadShape {
                  url "../mercury_a1/joint1.dae"
                }
              ]
            }
            HingeJoint {
              jointParameters HingeJointParameters {
                axis 0.000000 1.000000 -0.000004
              }
              device [
                RotationalMotor {
                  name "joint2_to_joint1"
                  minPosition -1.7453
                  maxPosition 1.7453
                  maxTorque 1000.0
                }
                PositionSensor {
                  name "joint2_to_joint1_sensor"
                }
              ]
              endPoint Solid {
                rotation -1.000000 0.000000 0.000000 1.570800
                children [
                  Pose {
                    rotation 0.707105 -0.707108 -0.000001 3.141591
                    children [
                      DEF joint2_visual CadShape {
                        url "../mercury_a1/joint2.dae"
                      }
                    ]
                  }
                  HingeJoint {
                    jointParameters HingeJointParameters {
                      axis 0.000000 -1.000000 -0.000004
                      anchor 0.000000 -0.110000 0.000000
                    }
                    device [
                      RotationalMotor {
                        name "joint3_to_joint2"
                        minPosition -2.8797
                        maxPosition 2.8797
                        maxTorque 1000.0
                      }
                      PositionSensor {
                        name "joint3_to_joint2_sensor"
                      }
                    ]
                    endPoint Solid {
                      translation 0.000000 -0.110000 0.000000
                      rotation 1.000000 0.000000 0.000000 1.570800
                      children [
                        Pose {
                          translation 0.000000 0.000000 0.038000
                          children [
                            DEF joint3_visual CadShape {
                              url "../mercury_a1/joint3.dae"
                            }
                          ]
                        }
                        HingeJoint {
                          jointParameters HingeJointParameters {
                            axis -0.000003 -1.000000 -0.000004
                            anchor 0.030000 0.000000 0.095000
                          }
                          device [
                            RotationalMotor {
                              name "joint4_to_joint3"
                              minPosition -3.0543
                              maxPosition 0.0174
                              maxTorque 1000.0
                            }
                            PositionSensor {
                              name "joint4_to_joint3_sensor"
                            }
                          ]
                          endPoint Solid {
                            translation 0.030000 0.000000 0.095000
                            rotation -0.000001 -0.707108 0.707105 3.141591
                            children [
                              Pose {
                                rotation 0.000000 0.000000 -1.000000 1.570800
                                children [
                                  DEF joint4_visual CadShape {
                                    url "../mercury_a1/joint4.dae"
                                  }
                                ]
                              }
                              HingeJoint {
                                jointParameters HingeJointParameters {
                                  axis -0.000000 -1.000000 0.000004
                                  anchor 0.030000 -0.126000 0.000000
                                }
                                device [
                                  RotationalMotor {
                                    name "joint5_to_joint4"
                                    minPosition -2.8797
                                    maxPosition 2.8797
                                    maxTorque 1000.0
                                  }
                                  PositionSensor {
                                    name "joint5_to_joint4_sensor"
                                  }
                                ]
                                endPoint Solid {
                                  translation 0.030000 -0.126000 0.000000
                                  rotation 0.000001 0.707105 -0.707108 3.141591
                                  children [
                                    Pose {
                                      translation 0.000000 0.000000 -0.069000
                                      children [
                                        DEF joint5_visual CadShape {
                                          url "../mercury_a1/joint5.dae"
                                        }
                                      ]
                                    }
                                    HingeJoint {
                                      jointParameters HingeJointParameters {
                                        axis 0.000000 -1.000000 -0.000004
                                        anchor 0.000000 0.000000 0.080000
                                      }
                                      device [
                                        RotationalMotor {
                                          name "joint6_to_joint5"
                                          minPosition -0.0174
                                          maxPosition 3.14159
                                          maxTorque 1000.0
                                        }
                                        PositionSensor {
                                          name "joint6_to_joint5_sensor"
                                        }
                                      ]
                                      endPoint Solid {
                                        translation 0.000000 0.000000 0.080000
                                        rotation 1.000000 0.000000 0.000000 1.570800
                                        children [
                                          Pose {
                                            translation 0.000000 0.000000 -0.025000
                                            rotation 0.000000 0.000000 -1.000000 1.570800
                                            children [
                                              DEF joint6_visual CadShape {
                                                url "../mercury_a1/joint6.dae"
                                              }
                                            ]
                                          }
                                          HingeJoint {
                                            jointParameters HingeJointParameters {
                                              axis 0.000000 -1.000000 -0.000004
                                              anchor 0.038000 -0.046000 0.000000
                                            }
                                            device [
                                              RotationalMotor {
                                                name "joint7_to_joint6"
                                                minPosition -2.8797
                                                maxPosition 2.8797
                                                maxTorque 1000.0
                                              }
                                              PositionSensor {
                                                name "joint7_to_joint6_sensor"
                                              }
                                            ]
                                            endPoint Solid {
                                              translation 0.038000 -0.046000 0.000000
                                              rotation 1.000000 0.000000 0.000000 1.570800
                                              children [
                                                Pose {
                                                  translation 0.000000 0.000000 -0.002000
                                                  rotation 0.000000 0.000000 -1.000000 1.570800
                                                  children [
                                                    DEF joint7_visual CadShape {
                                                      url "../mercury_a1/joint7.dae"
                                                    }
                                                  ]
                                                }
                                              ]
                                              name "joint7"
                                              boundingObject Pose {
                                                translation 0.000000 0.000000 -0.002000
                                                rotation 0.000000 0.000000 -1.000000 1.570800
                                                children [
                                                  DEF joint7 Mesh {
                                                    url "../mercury_a1/joint7.dae"
                                                  }
                                                ]
                                              }
                                              physics Physics {
                                              }
                                            }
                                          }
                                        ]
                                        name "joint6"
                                        boundingObject Pose {
                                          translation 0.000000 0.000000 -0.025000
                                          rotation 0.000000 0.000000 -1.000000 1.570800
                                          children [
                                            DEF joint6 Mesh {
                                              url "../mercury_a1/joint6.dae"
                                            }
                                          ]
                                        }
                                        physics Physics {
                                        }
                                      }
                                    }
                                  ]
                                  name "joint5"
                                  boundingObject Pose {
                                    translation 0.000000 0.000000 -0.069000
                                    children [
                                      DEF joint5 Mesh {
                                        url "../mercury_a1/joint5.dae"
                                      }
                                    ]
                                  }
                                  physics Physics {
                                  }
                                }
                              }
                            ]
                            name "joint4"
                            boundingObject Pose {
                              rotation 0.000000 0.000000 -1.000000 1.570800
                              children [
                                DEF joint4 Mesh {
                                  url "../mercury_a1/joint4.dae"
                                }
                              ]
                            }
                            physics Physics {
                            }
                          }
                        }
                      ]
                      name "joint3"
                      boundingObject Pose {
                        translation 0.000000 0.000000 0.038000
                        children [
                          DEF joint3 Mesh {
                            url "../mercury_a1/joint3.dae"
                          }
                        ]
                      }
                      physics Physics {
                      }
                    }
                  }
                ]
                name "joint2"
                boundingObject Pose {
                  rotation 0.707105 -0.707108 -0.000001 3.141591
                  children [
                    DEF joint2 Mesh {
                      url "../mercury_a1/joint2.dae"
                    }
                  ]
                }
                physics Physics {
                }
              }
            }
          ]
          name "joint1"
          boundingObject Pose {
            translation 0.000000 0.000000 -0.080000
            children [
              DEF joint1 Mesh {
                url "../mercury_a1/joint1.dae"
              }
            ]
          }
          physics Physics {
          }
        }
      }
    ]
    name IS name
    boundingObject DEF base Mesh {
      url "../mercury_a1/base.dae"
    }
    physics Physics {
    }
  }
}
